Workbook

Sheet Data Validation(Day4)
A1: ProductID | B1: Product | C1: Region | D1: Date | E1: Sales
A2: 101 | B2: Product A | C2: North | D2: 45292 | E2: 120 | H2: ProductID | I2: Product | J2: Region | K2: Date | L2: Sales
A3: 102 | B3: Product B | C3: South | D3: 45293 | E3: 150 | H3: 101 | I3: Product A | J3: North | K3: 45292 | L3: 100
A4: 103 | B4: Product A | C4: East | D4: 45294 | E4: 200 | H4: 102 | I4: Product C | J4: West | K4: 45301
A5: 104 | B5: Product C | C5: West | D5: 45295 | E5: 90 | H5: 103 | I5: Product B | L5: 200
A6: 105 | B6: Product B | C6: North | D6: 45296 | E6: 220 | H6: 104 | I6: Product B | L6: 22
A7: 106 | B7: Product A | C7: South | D7: 45297 | E7: 130 | H7: 105 | L7: 300
A8: 107 | B8: Product C | C8: North | D8: 45298 | E8: 300 | H8: 106 | L8: 55
A9: 108 | B9: Product B | C9: Esat | D9: 45299 | E9: 80 | H9: 107 | L9: 555
H10: 108 | L10: 555
H11: 109 | L11: 1000
H12: 110
H13: 111
B20: Product A
B21: Product B
B22: Product C
B23: Product D
B24: Product E

Sheet Data
D9: Name | E9: Sub1 | F9: Sub2 | G9: Sub3
D10: Aarav Mehta | E10: 90 | F10: 90 | G10: 90
D11: Riya Sen | E11: 83 | F11: 61 | G11: 77
D12: Kabir Sharma | E12: 60 | F12: 42 | G12: 84
D13: Ananya Das | E13: 100 | F13: 53 | G13: 96
D14: Vivaan Kapoor | E14: 88 | F14: 79 | G14: 71
D15: Meera Nair | E15: 39 | F15: 39 | G15: 41
D16: Arjun Roy | E16: 79 | F16: 40 | G16: 91
D17: Ishita Banerjee | E17: 78 | F17: 97 | G17: 51

Sheet Sheet3
D6: Name | E6: Sub1 | F6: Sub2 | G6: Sub3
D7: Aarav Mehta | E7: 90 | F7: 90 | G7: 90
D8: Riya Sen | E8: 83 | F8: 61 | G8: 77
D9: Kabir Sharma | E9: 60 | F9: 42 | G9: 84
D10: Ananya Das | E10: 100 | F10: 53 | G10: 96
D11: Vivaan Kapoor | E11: 88 | F11: 79 | G11: 71
D12: Meera Nair | E12: 39 | F12: 39 | G12: 41
D13: Arjun Roy | E13: 79 | F13: 40 | G13: 91
D14: Ishita Banerjee | E14: 78 | F14: 97 | G14: 51

Sheet Sheet4
D10: Name | E10: Sub1 | F10: Sub2 | G10: Sub3
D11: Aarav Mehta | E11: 90 | F11: 90 | G11: 90
D12: Riya Sen | E12: 83 | F12: 61 | G12: 77
D13: Kabir Sharma | E13: 60 | F13: 42 | G13: 84
D14: Ananya Das | E14: 100 | F14: 53 | G14: 96
D15: Vivaan Kapoor | E15: 88 | F15: 79 | G15: 71
D16: Meera Nair | E16: 39 | F16: 39 | G16: 41
D17: Arjun Roy | E17: 79 | F17: 40 | G17: 91
D18: Ishita Banerjee | E18: 78 | F18: 97 | G18: 51

Sheet Data Consolidation
B2: =SUM(Data:Sheet4!B2) -> 0 | C2: =SUM(Data:Sheet4!C2) -> 0 | D2: =SUM(Data:Sheet4!D2) -> 0 | G2: Sub1 | H2: Sub2 | I2: Sub3 | N2: Sub1 | O2: Sub2 | P2: Sub3
L3: Book1 | N3: =Data!$E$10 -> 90 | O3: =Data!$F$10 -> 90 | P3: =Data!$G$10 -> 90
L4: Book1 | N4: =Sheet3!$E$7 -> 90 | O4: =Sheet3!$F$7 -> 90 | P4: =Sheet3!$G$7 -> 90
L5: Book1 | N5: =Sheet4!$E$11 -> 90 | O5: =Sheet4!$F$11 -> 90 | P5: =Sheet4!$G$11 -> 90
B6: =SUM(Data:Sheet4!B3) -> 0 | C6: =SUM(Data:Sheet4!C3) -> 0 | D6: =SUM(Data:Sheet4!D3) -> 0 | F6: Aarav Mehta | G6: 270 | H6: 270 | I6: 270 | K6: Aarav Mehta | N6: =SUM(N3:N5) -> 270 | O6: =SUM(O3:O5) -> 270 | P6: =SUM(P3:P5) -> 270
L7: Book1 | N7: =Data!$E$11 -> 83 | O7: =Data!$F$11 -> 61 | P7: =Data!$G$11 -> 77
L8: Book1 | N8: =Sheet3!$E$8 -> 83 | O8: =Sheet3!$F$8 -> 61 | P8: =Sheet3!$G$8 -> 77
L9: Book1 | N9: =Sheet4!$E$12 -> 83 | O9: =Sheet4!$F$12 -> 61 | P9: =Sheet4!$G$12 -> 77
B10: =SUM(Data:Sheet4!B4) -> 0 | C10: =SUM(Data:Sheet4!C4) -> 0 | D10: =SUM(Data:Sheet4!D4) -> 0 | F10: Riya Sen | G10: 249 | H10: 183 | I10: 231 | K10: Riya Sen | N10: =SUM(N7:N9) -> 249 | O10: =SUM(O7:O9) -> 183 | P10: =SUM(P7:P9) -> 231
L11: Book1 | N11: =Data!$E$12 -> 60 | O11: =Data!$F$12 -> 42 | P11: =Data!$G$12 -> 84
L12: Book1 | N12: =Sheet3!$E$9 -> 60 | O12: =Sheet3!$F$9 -> 42 | P12: =Sheet3!$G$9 -> 84
L13: Book1 | N13: =Sheet4!$E$13 -> 60 | O13: =Sheet4!$F$13 -> 42 | P13: =Sheet4!$G$13 -> 84
B14: =SUM(Data:Sheet4!B5) -> 0 | C14: =SUM(Data:Sheet4!C5) -> 0 | D14: =SUM(Data:Sheet4!D5) -> 0 | F14: Kabir Sharma | G14: 180 | H14: 126 | I14: 252 | K14: Kabir Sharma | N14: =SUM(N11:N13) -> 180 | O14: =SUM(O11:O13) -> 126 | P14: =SUM(P11:P13) -> 252
L15: Book1 | N15: =Data!$E$13 -> 100 | O15: =Data!$F$13 -> 53 | P15: =Data!$G$13 -> 96
L16: Book1 | N16: =Sheet3!$E$10 -> 100 | O16: =Sheet3!$F$10 -> 53 | P16: =Sheet3!$G$10 -> 96
L17: Book1 | N17: =Sheet4!$E$14 -> 100 | O17: =Sheet4!$F$14 -> 53 | P17: =Sheet4!$G$14 -> 96
B18: =SUM(Data:Sheet4!B6) -> 0 | C18: =SUM(Data:Sheet4!C6) -> 0 | D18: =SUM(Data:Sheet4!D6) -> 0 | F18: Ananya Das | G18: 300 | H18: 159 | I18: 288 | K18: Ananya Das | N18: =SUM(N15:N17) -> 300 | O18: =SUM(O15:O17) -> 159 | P18: =SUM(P15:P17) -> 288
L19: Book1 | N19: =Data!$E$14 -> 88 | O19: =Data!$F$14 -> 79 | P19: =Data!$G$14 -> 71
L20: Book1 | N20: =Sheet3!$E$11 -> 88 | O20: =Sheet3!$F$11 -> 79 | P20: =Sheet3!$G$11 -> 71
L21: Book1 | N21: =Sheet4!$E$15 -> 88 | O21: =Sheet4!$F$15 -> 79 | P21: =Sheet4!$G$15 -> 71
B22: =SUM(Data:Sheet4!B7) -> 0 | C22: =SUM(Data:Sheet4!C7) -> 0 | D22: =SUM(Data:Sheet4!D7) -> 0 | F22: Vivaan Kapoor | G22: 264 | H22: 237 | I22: 213 | K22: Vivaan Kapoor | N22: =SUM(N19:N21) -> 264 | O22: =SUM(O19:O21) -> 237 | P22: =SUM(P19:P21) -> 213
L23: Book1 | N23: =Data!$E$15 -> 39 | O23: =Data!$F$15 -> 39 | P23: =Data!$G$15 -> 41
L24: Book1 | N24: =Sheet3!$E$12 -> 39 | O24: =Sheet3!$F$12 -> 39 | P24: =Sheet3!$G$12 -> 41
L25: Book1 | N25: =Sheet4!$E$16 -> 39 | O25: =Sheet4!$F$16 -> 39 | P25: =Sheet4!$G$16 -> 41
B26: =SUM(Data:Sheet4!B8) -> 0 | C26: =SUM(Data:Sheet4!C8) -> 0 | D26: =SUM(Data:Sheet4!D8) -> 0 | F26: Meera Nair | G26: 117 | H26: 117 | I26: 123 | K26: Meera Nair | N26: =SUM(N23:N25) -> 117 | O26: =SUM(O23:O25) -> 117 | P26: =SUM(P23:P25) -> 123
L27: Book1 | N27: =Data!$E$16 -> 79 | O27: =Data!$F$16 -> 40 | P27: =Data!$G$16 -> 91
L28: Book1 | N28: =Sheet3!$E$13 -> 79 | O28: =Sheet3!$F$13 -> 40 | P28: =Sheet3!$G$13 -> 91
L29: Book1 | N29: =Sheet4!$E$17 -> 79 | O29: =Sheet4!$F$17 -> 40 | P29: =Sheet4!$G$17 -> 91
B30: =SUM(Data:Sheet4!B9) -> 0 | C30: =SUM(Data:Sheet4!C9) -> 0 | D30: =SUM(Data:Sheet4!D9) -> 0 | F30: Arjun Roy | G30: 237 | H30: 120 | I30: 273 | K30: Arjun Roy | N30: =SUM(N27:N29) -> 237 | O30: =SUM(O27:O29) -> 120 | P30: =SUM(P27:P29) -> 273
L31: Book1 | N31: =Data!$E$17 -> 78 | O31: =Data!$F$17 -> 97 | P31: =Data!$G$17 -> 51
L32: Book1 | N32: =Sheet3!$E$14 -> 78 | O32: =Sheet3!$F$14 -> 97 | P32: =Sheet3!$G$14 -> 51
L33: Book1 | N33: =Sheet4!$E$18 -> 78 | O33: =Sheet4!$F$18 -> 97 | P33: =Sheet4!$G$18 -> 51
F34: Ishita Banerjee | G34: 234 | H34: 291 | I34: 153 | K34: Ishita Banerjee | N34: =SUM(N31:N33) -> 234 | O34: =SUM(O31:O33) -> 291 | P34: =SUM(P31:P33) -> 153
N38: Sub1 | O38: Sub2 | P38: Sub3
M39: Book1 | N39: =Data!$E$10 -> 90 | O39: =Data!$F$10 -> 90 | P39: =Data!$G$10 -> 90
M40: Book1 | N40: =Sheet3!$E$7 -> 90 | O40: =Sheet3!$F$7 -> 90 | P40: =Sheet3!$G$7 -> 90
M41: Book1 | N41: =Sheet4!$E$11 -> 90 | O41: =Sheet4!$F$11 -> 90 | P41: =Sheet4!$G$11 -> 90
L42: Aarav Mehta | N42: =SUM(N39:N41) -> 270 | O42: =SUM(O39:O41) -> 270 | P42: =SUM(P39:P41) -> 270
M43: Book1 | N43: =Data!$E$11 -> 83 | O43: =Data!$F$11 -> 61 | P43: =Data!$G$11 -> 77
M44: Book1 | N44: =Sheet3!$E$8 -> 83 | O44: =Sheet3!$F$8 -> 61 | P44: =Sheet3!$G$8 -> 77
...
