Workbook

Sheet VLOOKUP(LAB1) Question
A1: ProductID | B1: Product | C1: Price | E1: Questions
A2: 101 | B2: Product A | C2: 120 | E2: 1. Use VLOOKUP to find the product names for each ProductID in the Orders worksheet.
A3: 102 | B3: Product B | C3: 150 | E3: 2. Use VLOOKUP to find the price for each ProductID in the Orders worksheet, then calculate the TotalPrice by multiplying the Quantity by the Product Price.
A4: 103 | B4: Product C | C4: 200 | E4: 3. Use VLOOKUP to check if there are any ProductIDs in the Orders worksheet that do not exist in the Products worksheet.
A5: 104 | B5: Product D | C5: 90 | E5: 4. Assume a discount of 10% is given on all products. Use VLOOKUP to find the original price and then calculate the discounted price.
A6: 105 | B6: Product E | C6: 220 | E6: 5. Use VLOOKUP to find the price for each ProductID and then calculate the order value. Find the maximum order value from the list.
A7: 106 | B7: Product F | C7: 130 | E7: 6. Use VLOOKUP to find out which products from the Products worksheet have not been ordered.
E8: 7. Use VLOOKUP to find the Product name and summarize the total quantity sold for each product.
A9: OrderID | B9: ProductID | C9: Quantity
A10: 1 | B10: 101 | C10: 2
A11: 2 | B11: 103 | C11: 1
A12: 3 | B12: 105 | C12: 4
A13: 4 | B13: 106 | C13: 3
A14: 5 | B14: 102 | C14: 5
A15: 6 | B15: 104 | C15: 6

Sheet Products
A1: ProductID | B1: Product | C1: Price
A2: 101 | B2: Product A | C2: 120
A3: 102 | B3: Product B | C3: 150
A4: 103 | B4: Product C | C4: 200
A5: 104 | B5: Product D | C5: 90
A6: 105 | B6: Product E | C6: 220
A7: 106 | B7: Product F | C7: 130

Sheet Orders
A1: OrderID | B1: ProductID | C1: Quantity | D1: TotalPrice
A2: 1 | B2: 101 | C2: 2 | D2: =VLOOKUP(B2,Products!$A$2:$C$7,3,FALSE)*C2 -> 240
A3: 2 | B3: 103 | C3: 1 | D3: =VLOOKUP(B3,Products!$A$2:$C$7,3,FALSE)*C3 -> 200
A4: 3 | B4: 105 | C4: 4 | D4: =VLOOKUP(B4,Products!$A$2:$C$7,3,FALSE)*C4 -> 880
A5: 4 | B5: 106 | C5: 3 | D5: =VLOOKUP(B5,Products!$A$2:$C$7,3,FALSE)*C5 -> 390
A6: 5 | B6: 102 | C6: 5 | D6: =VLOOKUP(B6,Products!$A$2:$C$7,3,FALSE)*C6 -> 750
A7: 6 | B7: 104 | C7: 6 | D7: =VLOOKUP(B7,Products!$A$2:$C$7,3,FALSE)*C7 -> 540
A9: 1. Use VLOOKUP to find the product names for each ProductID in the Orders worksheet.
A10: ProductID | B10: Product Name
A11: 101 | B11: =VLOOKUP(A11,Products!$A$1:$C$7,2,FALSE) -> Product A
A12: 102 | B12: =VLOOKUP(A12,Products!$A$1:$C$7,2,FALSE) -> Product B
A13: 103 | B13: =VLOOKUP(A13,Products!$A$1:$C$7,2,FALSE) -> Product C
A14: 104 | B14: =VLOOKUP(A14,Products!$A$1:$C$7,2,FALSE) -> Product D
A15: 105 | B15: =VLOOKUP(A15,Products!$A$1:$C$7,2,FALSE) -> Product E
A16: 106 | B16: =VLOOKUP(A16,Products!$A$1:$C$7,2,FALSE) -> Product F
A18: 2. Use VLOOKUP to find the price for each ProductID in the Orders worksheet, then calculate the TotalPrice by multiplying the Quantity by the Product Price.
A20: OrderID | B20: ProductID | C20: Quantity | D20: Price | E20: Total Price
A21: 1 | B21: 101 | C21: 2 | D21: =VLOOKUP(B21,Products!$A$1:$C$7,3,FALSE) -> 120 | E21: =PRODUCT(C21,D21) -> 240
A22: 2 | B22: 103 | C22: 1 | D22: =VLOOKUP(B22,Products!$A$1:$C$7,3,FALSE) -> 200 | E22: =PRODUCT(C22,D22) -> 200
A23: 3 | B23: 105 | C23: 4 | D23: =VLOOKUP(B23,Products!$A$1:$C$7,3,FALSE) -> 220 | E23: =PRODUCT(C23,D23) -> 880
A24: 4 | B24: 106 | C24: 3 | D24: =VLOOKUP(B24,Products!$A$1:$C$7,3,FALSE) -> 130 | E24: =PRODUCT(C24,D24) -> 390
A25: 5 | B25: 102 | C25: 5 | D25: =VLOOKUP(B25,Products!$A$1:$C$7,3,FALSE) -> 150 | E25: =PRODUCT(C25,D25) -> 750
A26: 6 | B26: 104 | C26: 6 | D26: =VLOOKUP(B26,Products!$A$1:$C$7,3,FALSE) -> 90 | E26: =PRODUCT(C26,D26) -> 540
A28: 3. Use VLOOKUP to check if there are any ProductIDs in the Orders worksheet that do not exist in the Products worksheet.
A29: ProductID | B29: Exist
A30: 101 | B30: =IF(ISNA(VLOOKUP(A30,Products!$A$1:$C$7,1,FALSE)),"Not Found","Found") -> Found
A31: 102 | B31: =IF(ISNA(VLOOKUP(A31,Products!$A$1:$C$7,1,FALSE)),"Not Found","Found") -> Found
A32: 103 | B32: =IF(ISNA(VLOOKUP(A32,Products!$A$1:$C$7,1,FALSE)),"Not Found","Found") -> Found
A33: 104 | B33: =IF(ISNA(VLOOKUP(A33,Products!$A$1:$C$7,1,FALSE)),"Not Found","Found") -> Found
A34: 105 | B34: =IF(ISNA(VLOOKUP(A34,Products!$A$1:$C$7,1,FALSE)),"Not Found","Found") -> Found
A35: 106 | B35: =IF(ISNA(VLOOKUP(A35,Products!$A$1:$C$7,1,FALSE)),"Not Found","Found") -> Found
A37: 4. Assume a discount of 10% is given on all products. Use VLOOKUP to find the original price and then calculate the discounted price.
A38: ProductID | B38: Product | C38: Original Price | D38: Discounted Price | E38: Price After Discount
A39: 101 | B39: =VLOOKUP(A39,Products!$A$1:$C$7,2,FALSE) -> Product A | C39: =VLOOKUP(A39,Products!$A$1:$C$7,3,FALSE) -> 120 | D39: =VLOOKUP(A39,Products!$A$1:$C$7,3,FALSE)*10% -> 12 | E39: =C39-D39 -> 108
A40: 102 | B40: =VLOOKUP(A40,Products!$A$1:$C$7,2,FALSE) -> Product B | C40: =VLOOKUP(A40,Products!$A$1:$C$7,3,FALSE) -> 150 | D40: =VLOOKUP(A40,Products!$A$1:$C$7,3,FALSE)*10% -> 15 | E40: =C40-D40 -> 135
A41: 103 | B41: =VLOOKUP(A41,Products!$A$1:$C$7,2,FALSE) -> Product C | C41: =VLOOKUP(A41,Products!$A$1:$C$7,3,FALSE) -> 200 | D41: =VLOOKUP(A41,Products!$A$1:$C$7,3,FALSE)*10% -> 20 | E41: =C41-D41 -> 180
A42: 104 | B42: =VLOOKUP(A42,Products!$A$1:$C$7,2,FALSE) -> Product D | C42: =VLOOKUP(A42,Products!$A$1:$C$7,3,FALSE) -> 90 | D42: =VLOOKUP(A42,Products!$A$1:$C$7,3,FALSE)*10% -> 9 | E42: =C42-D42 -> 81
A43: 105 | B43: =VLOOKUP(A43,Products!$A$1:$C$7,2,FALSE) -> Product E | C43: =VLOOKUP(A43,Products!$A$1:$C$7,3,FALSE) -> 220 | D43: =VLOOKUP(A43,Products!$A$1:$C$7,3,FALSE)*10% -> 22 | E43: =C43-D43 -> 198
A44: 106 | B44: =VLOOKUP(A44,Products!$A$1:$C$7,2,FALSE) -> Product F | C44: =VLOOKUP(A44,Products!$A$1:$C$7,3,FALSE) -> 130 | D44: =VLOOKUP(A44,Products!$A$1:$C$7,3,FALSE)*10% -> 13 | E44: =C44-D44 -> 117
A46: 5. Use VLOOKUP to find the price for each ProductID and then calculate the order value. Find the maximum order value from the list.
...
